<?xml version="1.0"?>
<robot name="summit_xl" xmlns:xacro="http://www.ros.org/wiki/xacro">

  <xacro:macro name="summit_base">

	  <!-- Robot mechanical and motor parameters -->
	  <xacro:property name="PI" value="3.1415926535897931"/>
	  <xacro:property name="wheel_width" value="0.175" />

	<!-- BASE FOOTPRINT -->
        
    <gazebo>
        <plugin name="gazebo_ros_control" filename="libgazebo_ros_control.so">
            <robotNamespace>/lib_bot</robotNamespace>
        </plugin>
    </gazebo>
    
  <material name="black">
    <color rgba="0.0 0.0 0.0 1.0"/>
  </material>
  <material name="blue">
    <color rgba="0.203125 0.23828125 0.28515625 1.0"/>
  </material>
  <material name="green">
    <color rgba="0.0 0.8 0.0 1.0"/>
  </material>
  <material name="grey">
    <color rgba="0.2 0.2 0.2 1.0"/>
  </material>
  <material name="orange">
    <color rgba="1.0 0.423529411765 0.0392156862745 1.0"/>
  </material>
  <material name="brown">
    <color rgba="0.870588235294 0.811764705882 0.764705882353 1.0"/>
  </material>
  <material name="red">
    <color rgba="0.80078125 0.12890625 0.1328125 1.0"/>
  </material>
  <material name="white">
    <color rgba="1.0 1.0 1.0 1.0"/>
  </material>  
  
  <!--
  <gazebo reference="base_link">
    <material>Gazebo/Orange</material>
  </gazebo>
  -->
  <gazebo reference="link_left_wheel">
    <material>Gazebo/Blue</material>
  </gazebo>
  <gazebo reference="link_right_wheel">
    <material>Gazebo/Blue</material>
  </gazebo>
    <gazebo reference="tower_link">
    <material>Gazebo/Yellow</material>
  </gazebo>
  <gazebo reference="push_link">
    <material>Gazebo/Orange</material>
  </gazebo>
  <gazebo reference="jaw_1_link">
    <material>Gazebo/Blue</material>
  </gazebo>
  <gazebo reference="jaw_2_link">
    <material>Gazebo/Blue</material>
  </gazebo>
  
    
  <link name="base_link">
    <!-- pose and inertial -->
    <pose>0 0 0.1 0 0 0</pose>
    
    <inertial>
      <mass value="5"/>
      <origin rpy="0 0 0" xyz="0 0 0.1"/>
      <inertia ixx="0.0395416666667" ixy="0" ixz="0" iyy="0.106208333333" iyz="0" izz="0.106208333333"/>
    </inertial>
    
    <collision name="collision_chassis">
      <geometry>
       <mesh filename="package://summit_description/meshes/base/true_bae.dae" />
      </geometry>
    </collision>
    
    <visual>
      <origin rpy="0 0 0" xyz="0 0 0"/>
      <geometry>
        <mesh filename="package://summit_description/meshes/base/true_bae.dae" /> 
  
      </geometry>
      <material name="blue"/>
    </visual>
    
    </link>
  
  <!-- Create wheel right -->  
    

  
    <link name="tower_link">
        <visual>
            <origin rpy="0 0 0" xyz="0 0 0.275"/>
            <geometry>
                <mesh filename="package://summit_description/meshes/base/tower.dae" />
            </geometry>
        </visual>
        <collision>
            <origin xyz="0 0 0.275" rpy="0 0 0"/>
            <geometry>
                 <box size="0.025 0.15 0.60"/> 
            </geometry>
        </collision>
        <inertial>
            <origin xyz="0 0 0" rpy="0 0 0"/>
            <mass value="0.5" />
            <inertia ixx="0.0014541666666666665" ixy="0.0" ixz="0.0" iyy="0.0010416666666666667" iyz="0.0" izz="0.0022874999999999996"/>
        </inertial>
    </link>
    
    <link name="elevtor_link">
        <visual>
            <origin rpy="0 0 0" xyz="0 0 0"/>
            <geometry>
                 <mesh filename="package://summit_description/meshes/base/elevator.dae" />
            </geometry>
        </visual>
        <collision>
            <origin xyz="0 0 0" rpy="0 0 0"/>
            <geometry>
                <box size="0.15 0.18 0.05"/> 
            </geometry>
        </collision>
        <inertial>
            <origin xyz="0 0 0" rpy="0 0 0"/>
            <mass value="0.5" />
            <inertia ixx="0.0014541666666666665" ixy="0.0" ixz="0.0" iyy="0.0010416666666666667" iyz="0.0" izz="0.0022874999999999996"/>
        </inertial>
         <!--inertial>
            <origin xyz="0 0 0.275" rpy="0 0 0"/>
            <mass value="2.5" />
            <inertia ixx="0.07968750000000001" ixy="0.0" ixz="0.0" iyy="0.07513020833333334" iyz="0.0" izz="0.0048177083333333336"/>
        </inertial-->
    </link>
    
    <link name="push_link">
        <visual>
            <origin rpy="0 0 0" xyz="0 0 0"/>
            <geometry>
                <mesh filename="package://summit_description/meshes/base/push.dae" />
            </geometry>
        </visual>
        <collision>
            <origin xyz="0 0 0" rpy="0 0 0"/>
            <geometry>
                 <box size="0.01 0.18 0.15"/> 
            </geometry>
        </collision>
        <inertial>
            <origin xyz="0 0 0" rpy="0 0 0"/>
            <mass value="0.05" />
            <inertia ixx="0.00022874999999999998" ixy="0.0" ixz="0.0" iyy="9.416666666666666e-05" iyz="0.0" izz="0.00013541666666666666"/>
        </inertial>
    </link>
    
    <link name="jaw_1_link">
        <visual>
            <origin rpy="0 0 0" xyz="0 0 0"/>
            <geometry>
                <box size="0.20 0.01 0.05"/> 
            </geometry>
        </visual>
        <collision>
            <origin xyz="0 0 0" rpy="0 0 0"/>
            <geometry>
                 <box size="0.20 0.01 0.05"/> 
            </geometry>
        </collision>
        <inertial>
            <origin xyz="0 0 0" rpy="0 0 0"/>
            <mass value="0.05" />
            <inertia ixx="0.00022874999999999998" ixy="0.0" ixz="0.0" iyy="9.416666666666666e-05" iyz="0.0" izz="0.00013541666666666666"/>
        </inertial>
    </link>
    
    <link name="jaw_1_attach">


    <visual>
      <origin xyz="0 0 0" rpy="0 0 0"/>
      <geometry>
        <box size="0.01 0.025 0.03"/>
      </geometry>
    </visual>
    <collision>
      <origin xyz="0 0 0" rpy="0 0 0"/>
      <geometry>
        <box size="0.01 0.025 0.03"/>
      </geometry>
    </collision>
    <inertial>
            <origin xyz="0 0 0" rpy="0 0 0" />
            <mass value="0.05" />
            <inertia ixx="4.166666666666667e-05" ixy="0.0" ixz="0.0" iyy="2.166666666666667e-05" iyz="0.0" izz="2.166666666666667e-05" />
    </inertial>


  </link>
  <link name="jaw_2_attach">


    <visual>
      <origin xyz="0 0 0" rpy="0 0 0"/>
      <geometry>
        <box size="0.01 0.025 0.03"/>
      </geometry>
    </visual>
    <collision>
      <origin xyz="0 0 0" rpy="0 0 0"/>
      <geometry>
        <box size="0.01 0.025 0.03"/>
      </geometry>
    </collision>
    <inertial>
            <origin xyz="0 0 0" rpy="0 0 0" />
            <mass value="0.05" />
            <inertia ixx="4.166666666666667e-05" ixy="0.0" ixz="0.0" iyy="2.166666666666667e-05" iyz="0.0" izz="2.166666666666667e-05" />
    </inertial>


  </link>
    
    
    <link name="jaw_2_link">
        <visual>
            <origin rpy="0 0 0" xyz="0 0 0"/>
            <geometry>
                <box size="0.20 0.01 0.05"/> 
            </geometry>
        </visual>
        <collision>
            <origin xyz="0 0 0" rpy="0 0 0"/>
            <geometry>
                <box size="0.20 0.01 0.05"/> 
            </geometry>
        </collision>
        <inertial>
            <origin xyz="0 0 0" rpy="0 0 0"/>
            <mass value="0.05" />
            <inertia ixx="0.00022874999999999998" ixy="0.0" ixz="0.0" iyy="9.416666666666666e-05" iyz="0.0" izz="0.00013541666666666666"/>
        </inertial>
    </link>
    
    <link name="camera">


    <visual>
      <origin xyz="0 0 0" rpy="0 0 0"/>
      <geometry>
        <box size="0.01 0.05 0.05"/>
      </geometry>
    </visual>
    <collision>
      <origin xyz="0 0 0" rpy="0 0 0"/>
      <geometry>
        <box size="0.05 0.05 0.05"/>
      </geometry>
    </collision>
    <inertial>
            <origin xyz="0 0 0" rpy="0 0 0" />
            <mass value="0.05" />
            <inertia ixx="4.166666666666667e-05" ixy="0.0" ixz="0.0" iyy="2.166666666666667e-05" iyz="0.0" izz="2.166666666666667e-05" />
    </inertial>


  </link>
  
  <link name="hokuyo_bottom">
    <collision>
      <origin xyz="0 0 0" rpy="0 0 0"/>
      <geometry>
    <box size="0.1 0.1 0.1"/>
      </geometry>
    </collision>

    <visual>
      <origin xyz="0 0 0" rpy="0 0 0"/>
      <geometry>
          <mesh filename="package://summit_description/meshes/base/hokuyo.dae" />
      </geometry>
    </visual>

    <inertial>
      <mass value="1e-5" />
      <origin xyz="0 0 0" rpy="0 0 0"/>
      <inertia ixx="1e-6" ixy="0" ixz="0" iyy="1e-6" iyz="0" izz="1e-6" />
    </inertial>
  </link>
  
 
    


  <!-- Left Wheel link -->
    
<!-- 
  
 

    -->
  
  <joint name="base_link_tower_link_joint" type="fixed">
    <origin xyz="0.20 0 0" rpy="0 0 0"/>
    <parent link="base_link"/>
    <child link="tower_link"/>
 </joint>
    

  <joint name="tower_link_elevtor_link_joint" type="prismatic">
    <axis xyz="0 0 1"/>
    <parent link="tower_link"/>
    <child link="elevtor_link"/>
    <limit effort="1000.0" lower="0" upper="0.55" velocity="0.2"/>
    <origin rpy="0 0 0" xyz="0.090 0 0"/>
  </joint>
  
  <joint name="elevtor_link_push_link_joint" type="prismatic">
    <axis xyz="1 0 0"/>
    <parent link="elevtor_link"/>
    <child link="push_link"/>
    <limit effort="1000.0" lower="0" upper="0.14" velocity="0.2"/>
    <origin rpy="0 0 0" xyz="-0.070 0 0.1"/>
  </joint>
  
  <joint name="push_link_jaw_1_joint" type="prismatic">
    <axis xyz="0 1 0"/>
    <parent link="push_link"/>
    <child link="jaw_1_link"/>
    <limit effort="1000.0" lower="0" upper="0.075" velocity="0.2"/>
    <origin rpy="0 0 0" xyz="0.090 0.026 0"/>
  </joint>
  
  <joint name="push_link_jaw_2_joint" type="prismatic">
    <axis xyz="0 1 0"/>
    <parent link="push_link"/>
    <child link="jaw_2_link"/>
    <limit effort="1000.0" lower="-0.075" upper="0" velocity="0.2"/>
    <origin rpy="0 0 0" xyz="0.090 -0.026 0"/>
  </joint>
  
  <joint name="camera_joint" type="fixed">
        <axis xyz="0 1 0" />
        <origin xyz="0 0 0.1" rpy="0 0 0"/>
        <parent link="push_link"/>
        <child link="camera"/>
  </joint>
  
  <joint name="hokuyo_bottom_joint" type="fixed">
    <axis xyz="0 1 0" />
    <origin xyz="0 0 -.07" rpy="0 0 0"/>
    <parent link="tower_link"/>
    <child link="hokuyo_bottom"/>
  </joint>
  <joint name="attach_1_joint" type="fixed">
    <axis xyz="0 1 0" />
    <origin xyz="0.10 -0.025 0" rpy="0 0 0"/>
    <parent link="jaw_1_link"/>
    <child link="jaw_1_attach"/>
  </joint>
  <joint name="attach_2_joint" type="fixed">
    <axis xyz="0 1 0" />
    <origin xyz="0.10 0.025 0" rpy="0 0 0"/>
    <parent link="jaw_2_link"/>
    <child link="jaw_2_attach"/>
  </joint>
  
  
  
  
   <transmission name="tran1">
    <type>transmission_interface/SimpleTransmission</type>
    <joint name="tower_link_elevtor_link_joint">
      <!--hardwareInterface>EffortJointInterface</hardwareInterface-->
      <hardwareInterface>hardware_interface/PositionJointInterface</hardwareInterface>
    </joint>
    <actuator name="motor1">
      <!--hardwareInterface>EffortJointInterface</hardwareInterface-->
      <hardwareInterface>hardware_interface/PositionJointInterface</hardwareInterface>
      <mechanicalReduction>1</mechanicalReduction>
    </actuator>
  </transmission>
  
  <transmission name="tran2">
    <type>transmission_interface/SimpleTransmission</type>
    <joint name="elevtor_link_push_link_joint">
      <!--hardwareInterface>EffortJointInterface</hardwareInterface-->
      <hardwareInterface>hardware_interface/PositionJointInterface</hardwareInterface>
    </joint>
    <actuator name="motor2">
      <!--hardwareInterface>EffortJointInterface</hardwareInterface-->
      <hardwareInterface>hardware_interface/PositionJointInterface</hardwareInterface>
      <mechanicalReduction>1</mechanicalReduction>
    </actuator>
  </transmission>
  
  <transmission name="tran3">
    <type>transmission_interface/SimpleTransmission</type>
    <joint name="push_link_jaw_1_joint">
      <!--hardwareInterface>EffortJointInterface</hardwareInterface-->
      <hardwareInterface>hardware_interface/PositionJointInterface</hardwareInterface>
    </joint>
    <actuator name="motor3">
      <!--hardwareInterface>EffortJointInterface</hardwareInterface-->
      <hardwareInterface>hardware_interface/PositionJointInterface</hardwareInterface>
      <mechanicalReduction>1</mechanicalReduction>
    </actuator>
  </transmission>
  
  <transmission name="tran4">
    <type>transmission_interface/SimpleTransmission</type>
    <joint name="push_link_jaw_2_joint">
      <!--hardwareInterface>EffortJointInterface</hardwareInterface-->
      <hardwareInterface>hardware_interface/PositionJointInterface</hardwareInterface>
    </joint>
    <actuator name="motor4">
      <!--hardwareInterface>EffortJointInterface</hardwareInterface-->
      <hardwareInterface>hardware_interface/PositionJointInterface</hardwareInterface>
      <mechanicalReduction>1</mechanicalReduction>
    </actuator>
  </transmission>
  
 <gazebo reference="camera">
    <sensor type="camera" name="camera1">
      <update_rate>30.0</update_rate>
      <camera name="head">
        <horizontal_fov>1.3962634</horizontal_fov>
        <image>
          <width>800</width>
          <height>800</height>
          <format>R8G8B8</format>
        </image>
        <clip>
          <near>0.02</near>
          <far>300</far>
        </clip>
      </camera>
      <plugin name="camera_controller" filename="libgazebo_ros_camera.so">
        <alwaysOn>true</alwaysOn>
        <updateRate>0.0</updateRate>
        <cameraName>lib_bot/camera</cameraName>
        <imageTopicName>image_raw</imageTopicName>
        <cameraInfoTopicName>camera_info</cameraInfoTopicName>
        <frameName>camera</frameName>
        <hackBaseline>0.07</hackBaseline>
        <distortionK1>0.0</distortionK1>
        <distortionK2>0.0</distortionK2>
        <distortionK3>0.0</distortionK3>
        <distortionT1>0.0</distortionT1>
        <distortionT2>0.0</distortionT2>
      </plugin>
    </sensor>
  </gazebo>
  
  <!--
  < gazebo reference="hokuyo_bottom">
    <sensor type="gpu_ray" name="head_hokuyo_sensor">
      <pose>0 0 0 0 0 0</pose>
      <visualize>true</visualize>
      <update_rate>40</update_rate>
      <ray>
        <scan>
          <horizontal>
            <samples>720</samples>
            <resolution>1</resolution>
            <min_angle>-1.57</min_angle>
            <max_angle>1.57</max_angle>
          </horizontal>
        </scan>
        <range>
          <min>0.10</min>
          <max>30.0</max>
          <resolution>0.01</resolution>
        </range>
        <noise>
          <type>gaussian</type>
          <mean>0.0</mean>
          <stddev>0.01</stddev>
        </noise>
      </ray>
      <plugin name="gazebo_ros_head_hokuyo_controller" filename="libgazebo_ros_gpu_laser.so">
        <topicName>/scan</topicName>
        <frameName>hokuyo_bottom</frameName>
      </plugin>
    </sensor>
  </gazebo >
  -->
  
  
 
  
  
  <gazebo reference="hokuyo_bottom">
    <sensor type="ray" name="head_hokuyo_sensor">
      <pose>0 0 0 0 0 0</pose>
      <visualize>true</visualize>
      <update_rate>40</update_rate>
      <ray>
        <scan>
          <horizontal>
            <samples>720</samples>
            <resolution>1</resolution>
            <min_angle>-1.570796</min_angle>
            <max_angle>1.570796</max_angle>
          </horizontal>
        </scan>
        <range>
          <min>0.10</min>
          <max>30.0</max>
          <resolution>0.01</resolution>
        </range>
        <noise>
          <type>gaussian</type>
          <!-- Noise parameters based on published spec for Hokuyo laser
               achieving "+-30mm" accuracy at range < 10m.  A mean of 0.0m and
               stddev of 0.01m will put 99.7% of samples within 0.03m of the true
               reading. -->
          <mean>0.0</mean>
          <stddev>0.01</stddev>
        </noise>
      </ray>
      <plugin name="gazebo_ros_head_hokuyo_controller" filename="libgazebo_ros_laser.so">
        <topicName>/mybot/laser/scan_bottom</topicName>
        <frameName>hokuyo_bottom</frameName>
      </plugin>
    </sensor>
  </gazebo>
  
  <gazebo>
    <plugin name="omni_steering" filename="libgazebo_ros_planar_move.so">
      <commandTopic>cmd_vel</commandTopic>
      <odometryTopic>odom</odometryTopic>
      <odometryFrame>odom</odometryFrame>
      <odometryRate>100.0</odometryRate>
      <robotBaseFrame>base_link</robotBaseFrame>
      <publishTF>false</publishTF>
      <publishWheelJointState>false</publishWheelJointState>
    </plugin>
  </gazebo>

  </xacro:macro>

</robot>

