<?xml version="1.0"?>

<robot name="lib_bot">
    <gazebo>
        <plugin name="gazebo_ros_control" filename="libgazebo_ros_control.so">
            <robotNamespace>/lib_bot</robotNamespace>
        </plugin>
    </gazebo>
    
    
    <link 
    name="base_link">
        <visual>
            <origin rpy="0 0 0" xyz="0 0 0"/>
            <geometry>
               <box size="0.5 0.3 0.05"/> 
            </geometry>
        </visual>
        <collision>
            <origin xyz="0 0 0" rpy="0 0 0"/>
            <geometry>
               <box size="0.5 0.3 0.05"/> 
            </geometry>
        </collision>
        <inertial>
            <origin xyz="0 0 0" rpy="0 0 0"/>
            <mass value="18" />
            <inertia ixx="0.13874999999999998" ixy="0.0" ixz="0.0" iyy="0.37875000000000003" iyz="0.0" izz="0.51"/>
        </inertial>
    </link>
    
    <link name="tower_link">
        <visual>
            <origin rpy="0 0 0" xyz="0 0 0.275"/>
            <geometry>
                <box size="0.025 0.15 0.60"/> 
            </geometry>
        </visual>
        <collision>
            <origin xyz="0 0 0.275" rpy="0 0 0"/>
            <geometry>
                 <box size="0.025 0.15 0.60"/> 
            </geometry>
        </collision>
        <inertial>
            <origin xyz="0 0 0.275" rpy="0 0 0"/>
            <mass value="10" />
            <inertia ixx="0.31875000000000003" ixy="0.0" ixz="0.0" iyy="0.300520833333" iyz="0.0" izz="0.0192708333333"/>
        </inertial>
    </link>
    
    <link name="elevtor_link">
        <visual>
            <origin rpy="0 0 0" xyz="0 0 0"/>
            <geometry>
                <box size="0.15 0.18 0.05"/> 
            </geometry>
        </visual>
        <collision>
            <origin xyz="0 0 0" rpy="0 0 0"/>
            <geometry>
                <box size="0.15 0.18 0.05"/> 
            </geometry>
        </collision>
        <inertial>
            <origin xyz="0 0 0" rpy="0 0 0"/>
            <mass value="0.5" />
            <inertia ixx="0.0014541666666666665" ixy="0.0" ixz="0.0" iyy="0.0010416666666666667" iyz="0.0" izz="0.0022874999999999996"/>
        </inertial>
    </link>
    
    <link name="push_link">
        <visual>
            <origin rpy="0 0 0" xyz="0 0 0"/>
            <geometry>
                <box size="0.01 0.18 0.15"/> 
            </geometry>
        </visual>
        <collision>
            <origin xyz="0 0 0" rpy="0 0 0"/>
            <geometry>
                 <box size="0.01 0.18 0.15"/> 
            </geometry>
        </collision>
        <inertial>
            <origin xyz="0 0 0" rpy="0 0 0"/>
            <mass value="0.05" />
            <inertia ixx="0.0013724999999999998" ixy="0.0" ixz="0.0" iyy="0.0006025" iyz="0.0" izz="0.0008499999999999998"/>
        </inertial>
    </link>
    
    <link name="jaw_1_link">
        <visual>
            <origin rpy="0 0 0" xyz="0 0 0"/>
            <geometry>
                <box size="0.15 0.01 0.05"/> 
            </geometry>
        </visual>
        <collision>
            <origin xyz="0 0 0" rpy="0 0 0"/>
            <geometry>
                 <box size="0.15 0.01 0.05"/> 
            </geometry>
        </collision>
        <inertial>
            <origin xyz="0 0 0" rpy="0 0 0"/>
            <mass value="0.05" />
            <inertia ixx="0.0013724999999999998" ixy="0.0" ixz="0.0" iyy="0.0006025" iyz="0.0" izz="0.0008499999999999998"/>
        </inertial>
    </link>
    
    <link name="jaw_2_link">
        <visual>
            <origin rpy="0 0 0" xyz="0 0 0"/>
            <geometry>
                <box size="0.15 0.01 0.05"/> 
            </geometry>
        </visual>
        <collision>
            <origin xyz="0 0 0" rpy="0 0 0"/>
            <geometry>
                <box size="0.15 0.01 0.05"/> 
            </geometry>
        </collision>
        <inertial>
            <origin xyz="0 0 0" rpy="0 0 0"/>
            <mass value="0.05" />
            <inertia ixx="0.0013724999999999998" ixy="0.0" ixz="0.0" iyy="0.0006025" iyz="0.0" izz="0.0008499999999999998"/>
        </inertial>
    </link>
    
    <link name="camera">


    <visual>
      <origin xyz="0 0 0" rpy="0 0 0"/>
      <geometry>
        <box size="0.01 0.05 0.05"/>
      </geometry>
    </visual>
    <collision>
      <origin xyz="0 0 0" rpy="0 0 0"/>
      <geometry>
        <box size="0.05 0.05 0.05"/>
      </geometry>
    </collision>
    <inertial>
            <origin xyz="0 0 0" rpy="0 0 0" />
            <mass value="0.05" />
            <inertia ixx="4.166666666666667e-05" ixy="0.0" ixz="0.0" iyy="2.166666666666667e-05" iyz="0.0" izz="2.166666666666667e-05" />
        </inertial>


  </link>
    
   <!-- JOINTS --> 
    
  <joint name="base_link_tower_link_joint" type="fixed">
    <origin xyz="0.265 0 0" rpy="0 0 0"/>
    <parent link="base_link"/>
    <child link="tower_link"/>
 </joint>
    

  <joint name="tower_link_elevtor_link_joint" type="prismatic">
    <axis xyz="0 0 1"/>
    <parent link="tower_link"/>
    <child link="elevtor_link"/>
    <limit effort="1000.0" lower="0" upper="0.55" velocity="0.2"/>
    <origin rpy="0 0 0" xyz="0.090 0 0"/>
  </joint>
  
  <joint name="elevtor_link_push_link_joint" type="prismatic">
    <axis xyz="1 0 0"/>
    <parent link="elevtor_link"/>
    <child link="push_link"/>
    <limit effort="1000.0" lower="0" upper="0.14" velocity="0.2"/>
    <origin rpy="0 0 0" xyz="-0.070 0 0.1"/>
  </joint>
  
  <joint name="push_link_jaw_1_joint" type="prismatic">
    <axis xyz="0 1 0"/>
    <parent link="push_link"/>
    <child link="jaw_1_link"/>
    <limit effort="1000.0" lower="0" upper="0.075" velocity="0.2"/>
    <origin rpy="0 0 0" xyz="0.080 0.006 0"/>
  </joint>
  
  <joint name="push_link_jaw_2_joint" type="prismatic">
    <axis xyz="0 1 0"/>
    <parent link="push_link"/>
    <child link="jaw_2_link"/>
    <limit effort="1000.0" lower="-0.075" upper="0" velocity="0.2"/>
    <origin rpy="0 0 0" xyz="0.080 -0.006 0"/>
  </joint>
  <joint name="camera_joint" type="fixed">
        <axis xyz="0 1 0" />
        <origin xyz="0 0 0.1" rpy="0 0 0"/>
        <parent link="push_link"/>
        <child link="camera"/>
    </joint>
  <!-- TRANSMISSIONS-->
  
  
  <transmission name="tran1">
    <type>transmission_interface/SimpleTransmission</type>
    <joint name="tower_link_elevtor_link_joint">
      <!--hardwareInterface>EffortJointInterface</hardwareInterface-->
      <hardwareInterface>hardware_interface/PositionJointInterface</hardwareInterface>
    </joint>
    <actuator name="motor1">
      <!--hardwareInterface>EffortJointInterface</hardwareInterface-->
      <hardwareInterface>hardware_interface/PositionJointInterface</hardwareInterface>
      <mechanicalReduction>1</mechanicalReduction>
    </actuator>
  </transmission>
  
  <transmission name="tran2">
    <type>transmission_interface/SimpleTransmission</type>
    <joint name="elevtor_link_push_link_joint">
      <!--hardwareInterface>EffortJointInterface</hardwareInterface-->
      <hardwareInterface>hardware_interface/PositionJointInterface</hardwareInterface>
    </joint>
    <actuator name="motor2">
      <!--hardwareInterface>EffortJointInterface</hardwareInterface-->
      <hardwareInterface>hardware_interface/PositionJointInterface</hardwareInterface>
      <mechanicalReduction>1</mechanicalReduction>
    </actuator>
  </transmission>
  
  <transmission name="tran3">
    <type>transmission_interface/SimpleTransmission</type>
    <joint name="push_link_jaw_1_joint">
      <!--hardwareInterface>EffortJointInterface</hardwareInterface-->
      <hardwareInterface>hardware_interface/PositionJointInterface</hardwareInterface>
    </joint>
    <actuator name="motor3">
      <!--hardwareInterface>EffortJointInterface</hardwareInterface-->
      <hardwareInterface>hardware_interface/PositionJointInterface</hardwareInterface>
      <mechanicalReduction>1</mechanicalReduction>
    </actuator>
  </transmission>
  
  <transmission name="tran4">
    <type>transmission_interface/SimpleTransmission</type>
    <joint name="push_link_jaw_2_joint">
      <!--hardwareInterface>EffortJointInterface</hardwareInterface-->
      <hardwareInterface>hardware_interface/PositionJointInterface</hardwareInterface>
    </joint>
    <actuator name="motor4">
      <!--hardwareInterface>EffortJointInterface</hardwareInterface-->
      <hardwareInterface>hardware_interface/PositionJointInterface</hardwareInterface>
      <mechanicalReduction>1</mechanicalReduction>
    </actuator>
  </transmission>
  
 <gazebo reference="camera">
    <sensor type="camera" name="camera1">
      <update_rate>30.0</update_rate>
      <camera name="head">
        <horizontal_fov>1.3962634</horizontal_fov>
        <image>
          <width>800</width>
          <height>800</height>
          <format>R8G8B8</format>
        </image>
        <clip>
          <near>0.02</near>
          <far>300</far>
        </clip>
      </camera>
      <plugin name="camera_controller" filename="libgazebo_ros_camera.so">
        <alwaysOn>true</alwaysOn>
        <updateRate>0.0</updateRate>
        <cameraName>mybot/camera1</cameraName>
        <imageTopicName>image_raw</imageTopicName>
        <cameraInfoTopicName>camera_info</cameraInfoTopicName>
        <frameName>camera</frameName>
        <hackBaseline>0.07</hackBaseline>
        <distortionK1>0.0</distortionK1>
        <distortionK2>0.0</distortionK2>
        <distortionK3>0.0</distortionK3>
        <distortionT1>0.0</distortionT1>
        <distortionT2>0.0</distortionT2>
      </plugin>
    </sensor>
  </gazebo>
</robot>
