<?xml version="1.0" ?>
<robot name="lib_bot">

    <link name="base_link">
        <!-- pose and inertial -->
        <pose>0 0 0.1 0 0 0</pose>
        
<inertial>
            <mass value="5" />
            <origin rpy="0 0 0" xyz="0 0 0.1" />
            <inertia ixx="0.0395416666667" ixy="0" ixz="0" iyy="0.106208333333" iyz="0" izz="0.106208333333" />
        </inertial>

        <collision name="collision_chassis">
            <geometry>
                <box size="0.5 0.3 0.07" />
            </geometry>
        </collision>
        <visual>
            <origin rpy="0 0 0" xyz="0 0 0" />
            <geometry>
                <box size="0.5 0.3 0.07" />
            </geometry>
        </visual>
        <!-- caster front -->
        <collision name="caster_front_collision">
            <origin rpy=" 0 0 0" xyz="0.35 0 -0.05" />
            <geometry>
                <sphere radius="0.05" />
            </geometry>
            <surface>
                <friction>
                    <ode>
                        <mu>0</mu>
                        <mu2>0</mu2>
                        <slip1>0.0</slip1>
                        <slip2>0.0</slip2>
                    </ode>
                </friction>
            </surface>
        </collision>
        <visual name="caster_front_visual">
            <origin rpy=" 0 0 0" xyz="0.2 0 -0.05" />
            <geometry>
                <sphere radius="0.05" />
            </geometry>
        </visual>
    </link>
    <!-- Create wheel right -->
    <link name="link_right_wheel">
        <!-- inertial>
      <mass value="0.2"/>
      <origin rpy="0 1.5707 1.5707" xyz="0 0 0"/>
      <inertia ixx="0.00052666666" ixy="0" ixz="0" iyy="0.00052666666" iyz="0" izz="0.001"/>
    </inertial -->
        
<inertial>
            <origin xyz="0 0 0" rpy="0 0 0" />
            <mass value="0.5" />
            <inertia ixx="0.0014541666666666665" ixy="0.0" ixz="0.0" iyy="0.0010416666666666667" iyz="0.0" izz="0.0022874999999999996" />
        </inertial>
        <collision name="link_right_wheel_collision">
            <origin rpy="0 1.5707 1.5707" xyz="0 0 0" />
            <geometry>
                <cylinder length="0.04" radius="0.1" />
            </geometry>
        </collision>
        <visual name="link_right_wheel_visual">
            <origin rpy="0 1.5707 1.5707" xyz="0 0 0" />
            <geometry>
                <cylinder length="0.04" radius="0.1" />
            </geometry>
        </visual>
    </link>
    <link name="tower_link">
        <visual>
            <origin rpy="0 0 0" xyz="0 0 0.275" />
            <geometry>
                <box size="0.025 0.15 0.60" />
            </geometry>
        </visual>
        <collision>
            <origin xyz="0 0 0.275" rpy="0 0 0" />
            <geometry>
                <box size="0.025 0.15 0.60" />
            </geometry>
        </collision>
        <inertial>
            <origin xyz="0 0 0" rpy="0 0 0" />
            <mass value="0.5" />
            <inertia ixx="0.0014541666666666665" ixy="0.0" ixz="0.0" iyy="0.0010416666666666667" iyz="0.0" izz="0.0022874999999999996" />
        </inertial>
    </link>
    <link name="elevtor_link">
        <visual>
            <origin rpy="0 0 0" xyz="0 0 0" />
            <geometry>
                <box size="0.15 0.18 0.05" />
            </geometry>
        </visual>
        <collision>
            <origin xyz="0 0 0" rpy="0 0 0" />
            <geometry>
                <box size="0.15 0.18 0.05" />
            </geometry>
        </collision>
        <inertial>
            <origin xyz="0 0 0" rpy="0 0 0" />
            <mass value="0.5" />
            <inertia ixx="0.0014541666666666665" ixy="0.0" ixz="0.0" iyy="0.0010416666666666667" iyz="0.0" izz="0.0022874999999999996" />
        </inertial>
        <!--inertial>
            <origin xyz="0 0 0.275" rpy="0 0 0"/>
            <mass value="2.5" />
            <inertia ixx="0.07968750000000001" ixy="0.0" ixz="0.0" iyy="0.07513020833333334" iyz="0.0" izz="0.0048177083333333336"/>
        </inertial-->
    </link>
    <link name="push_link">
        <visual>
            <origin rpy="0 0 0" xyz="0 0 0" />
            <geometry>
                <box size="0.01 0.18 0.15" />
            </geometry>
        </visual>
        <collision>
            <origin xyz="0 0 0" rpy="0 0 0" />
            <geometry>
                <box size="0.01 0.18 0.15" />
            </geometry>
        </collision>
        <inertial>
            <origin xyz="0 0 0" rpy="0 0 0" />
            <mass value="0.05" />
            <inertia ixx="0.00022874999999999998" ixy="0.0" ixz="0.0" iyy="9.416666666666666e-05" iyz="0.0" izz="0.00013541666666666666" />
        </inertial>
    </link>
    <link name="jaw_1_link">
        <visual>
            <origin rpy="0 0 0" xyz="0 0 0" />
            <geometry>
                <box size="0.15 0.01 0.05" />
            </geometry>
        </visual>
        <collision>
            <origin xyz="0 0 0" rpy="0 0 0" />
            <geometry>
                <box size="0.15 0.01 0.05" />
            </geometry>
        </collision>
        <inertial>
            <origin xyz="0 0 0" rpy="0 0 0" />
            <mass value="0.05" />
            <inertia ixx="0.00022874999999999998" ixy="0.0" ixz="0.0" iyy="9.416666666666666e-05" iyz="0.0" izz="0.00013541666666666666" />
        </inertial>
    </link>
    <link name="jaw_2_link">
        <visual>
            <origin rpy="0 0 0" xyz="0 0 0" />
            <geometry>
                <box size="0.15 0.01 0.05" />
            </geometry>
        </visual>
        <collision>
            <origin xyz="0 0 0" rpy="0 0 0" />
            <geometry>
                <box size="0.15 0.01 0.05" />
            </geometry>
        </collision>
        <inertial>
            <origin xyz="0 0 0" rpy="0 0 0" />
            <mass value="0.05" />
            <inertia ixx="0.00022874999999999998" ixy="0.0" ixz="0.0" iyy="9.416666666666666e-05" iyz="0.0" izz="0.00013541666666666666" />
        </inertial>
    </link>
    <link name="camera">
        <visual>
            <origin xyz="0 0 0" rpy="0 0 0" />
            <geometry>
                <box size="0.01 0.05 0.05" />
            </geometry>
        </visual>
        <collision>
            <origin xyz="0 0 0" rpy="0 0 0" />
            <geometry>
                <box size="0.05 0.05 0.05" />
            </geometry>
        </collision>
        <inertial>
            <origin xyz="0 0 0" rpy="0 0 0" />
            <mass value="0.05" />
            <inertia ixx="4.166666666666667e-05" ixy="0.0" ixz="0.0" iyy="2.166666666666667e-05" iyz="0.0" izz="2.166666666666667e-05" />
        </inertial>
    </link>
    <!--   Joint for right wheel  -->
    <joint name="joint_right_wheel" type="continuous">
        <origin rpy="0 0 0" xyz="-0.05 0.15 0" />
        <child link="link_right_wheel" />
        <parent link="base_link" />
        <axis rpy="0 0 0" xyz="0 1 0" />
        <limit effort="10000" velocity="1000" />
        <joint_properties damping="1.0" friction="1.0" />
    </joint>
    <!-- Left Wheel link -->
    <link name="link_left_wheel">
        <!-- inertial>
      <mass value="0.2"/>
      <origin rpy="0 1.5707 1.5707" xyz="0 0 0"/>
      <inertia ixx="0.00052666666" ixy="0" ixz="0" iyy="0.00052666666" iyz="0" izz="0.001"/>
    </inertial -->
        <inertial>
            <origin xyz="0 0 0" rpy="0 0 0" />
            <mass value="0.5" />
            <inertia ixx="0.0014541666666666665" ixy="0.0" ixz="0.0" iyy="0.0010416666666666667" iyz="0.0" izz="0.0022874999999999996" />
        </inertial>
        <collision name="link_left_wheel_collision">
            <origin rpy="0 1.5707 1.5707" xyz="0 0 0" />
            <geometry>
                <cylinder length="0.04" radius="0.1" />
            </geometry>
        </collision>
        <visual name="link_left_wheel_visual">
            <origin rpy="0 1.5707 1.5707" xyz="0 0 0" />
            <geometry>
                <cylinder length="0.04" radius="0.1" />
            </geometry>
        </visual>
    </link>
    <link name="hokuyo">
        <collision>
            <origin xyz="0 0 0" rpy="0 0 0" />
            <geometry>
                <box size="0.1 0.1 0.1" />
            </geometry>
        </collision>
        <visual>
            <origin xyz="0 0 0" rpy="0 0 0" />
            <geometry>
                <box size="0.1 0.1 0.1" />
            </geometry>
        </visual>
        <inertial>
            <mass value="1e-5" />
            <origin xyz="0 0 0" rpy="0 0 0" />
            <inertia ixx="1e-6" ixy="0" ixz="0" iyy="1e-6" iyz="0" izz="1e-6" />
        </inertial>
    </link>
    <!--   Joint for right wheel  -->
    <joint name="joint_left_wheel" type="continuous">
        <origin rpy="0 0 0" xyz="-0.05 -0.15 0" />
        <child link="link_left_wheel" />
        <parent link="base_link" />
        <axis rpy="0 0 0" xyz="0 1 0" />
        <limit effort="10000" velocity="1000" />
        <joint_properties damping="1.0" friction="1.0" />
    </joint>
    <joint name="base_link_tower_link_joint" type="fixed">
        <origin xyz="0.265 0 0" rpy="0 0 0" />
        <parent link="base_link" />
        <child link="tower_link" />
    </joint>
    <joint name="tower_link_elevtor_link_joint" type="prismatic">
        <axis xyz="0 0 1" />
        <parent link="tower_link" />
        <child link="elevtor_link" />
        <limit effort="1000.0" lower="0" upper="0.55" velocity="0.2" />
        <origin rpy="0 0 0" xyz="0.090 0 0" />
    </joint>
    <joint name="elevtor_link_push_link_joint" type="prismatic">
        <axis xyz="1 0 0" />
        <parent link="elevtor_link" />
        <child link="push_link" />
        <limit effort="1000.0" lower="0" upper="0.14" velocity="0.2" />
        <origin rpy="0 0 0" xyz="-0.070 0 0.1" />
    </joint>
    <joint name="push_link_jaw_1_joint" type="prismatic">
        <axis xyz="0 1 0" />
        <parent link="push_link" />
        <child link="jaw_1_link" />
        <limit effort="1000.0" lower="0" upper="0.075" velocity="0.2" />
        <origin rpy="0 0 0" xyz="0.080 0.006 0" />
    </joint>
    <joint name="push_link_jaw_2_joint" type="prismatic">
        <axis xyz="0 1 0" />
        <parent link="push_link" />
        <child link="jaw_2_link" />
        <limit effort="1000.0" lower="-0.075" upper="0" velocity="0.2" />
        <origin rpy="0 0 0" xyz="0.080 -0.006 0" />
    </joint>
    <joint name="camera_joint" type="fixed">
        <axis xyz="0 1 0" />
        <origin xyz="0 0 0.1" rpy="0 0 0" />
        <parent link="push_link" />
        <child link="camera" />
    </joint>
    <joint name="hokuyo_joint" type="fixed">
        <axis xyz="0 1 0" />
        <origin xyz="0 0 .1" rpy="0 0 3.14" />
        <parent link="base_link" />
        <child link="hokuyo" />
    </joint>


    <transmission name="trans_joint_right_wheel">
        <type>transmission_interface/SimpleTransmission</type>
        <joint name="joint_right_wheel">
            <hardwareInterface>hardware_interface/EffortJointInterface</hardwareInterface>
        </joint>
        <actuator name="joint_right_wheel_motor">
            <hardwareInterface>hardware_interface/EffortJointInterface</hardwareInterface>
            <mechanicalReduction>1</mechanicalReduction>
        </actuator>
    </transmission>
    <transmission name="trans_joint_left_wheel">
        <type>transmission_interface/SimpleTransmission</type>
        <joint name="joint_left_wheel">
            <hardwareInterface>hardware_interface/EffortJointInterface</hardwareInterface>
        </joint>
        <actuator name="joint_left_wheel_motor">
            <hardwareInterface>hardware_interface/EffortJointInterface</hardwareInterface>
            <mechanicalReduction>1</mechanicalReduction>
        </actuator>
    </transmission>
    <transmission name="trans_tower_link_elevtor_link_joint">
        <type>transmission_interface/SimpleTransmission</type>
        <joint name="tower_link_elevtor_link_joint">
            <hardwareInterface>hardware_interface/EffortJointInterface</hardwareInterface>
        </joint>
        <actuator name="tower_link_elevtor_link_joint_motor">
            <hardwareInterface>hardware_interface/EffortJointInterface</hardwareInterface>
            <mechanicalReduction>1</mechanicalReduction>
        </actuator>
    </transmission>
    <transmission name="trans_elevtor_link_push_link_joint">
        <type>transmission_interface/SimpleTransmission</type>
        <joint name="elevtor_link_push_link_joint">
            <hardwareInterface>hardware_interface/EffortJointInterface</hardwareInterface>
        </joint>
        <actuator name="elevtor_link_push_link_joint_motor">
            <hardwareInterface>hardware_interface/EffortJointInterface</hardwareInterface>
            <mechanicalReduction>1</mechanicalReduction>
        </actuator>
    </transmission>
    <transmission name="trans_push_link_jaw_1_joint">
        <type>transmission_interface/SimpleTransmission</type>
        <joint name="push_link_jaw_1_joint">
            <hardwareInterface>hardware_interface/EffortJointInterface</hardwareInterface>
        </joint>
        <actuator name="push_link_jaw_1_joint_motor">
            <hardwareInterface>hardware_interface/EffortJointInterface</hardwareInterface>
            <mechanicalReduction>1</mechanicalReduction>
        </actuator>
    </transmission>
    <transmission name="trans_push_link_jaw_2_joint">
        <type>transmission_interface/SimpleTransmission</type>
        <joint name="push_link_jaw_2_joint">
            <hardwareInterface>hardware_interface/EffortJointInterface</hardwareInterface>
        </joint>
        <actuator name="push_link_jaw_2_joint_motor">
            <hardwareInterface>hardware_interface/EffortJointInterface</hardwareInterface>
            <mechanicalReduction>1</mechanicalReduction>
        </actuator>
    </transmission>
    <gazebo>
        <plugin name="gazebo_ros_control" filename="libgazebo_ros_control.so">
            <robotNamespace>/</robotNamespace>
        </plugin>
    </gazebo>
</robot>
